<?xml version="1.0"?>
<robot name="simple_humanoid">

  <link name="base_link">
    <visual>
      <geometry><box size="0.2 0.4 0.6"/></geometry>
    </visual>
    <collision>
      <geometry><box size="0.2 0.4 0.6"/></geometry>
    </collision>
    <inertial>
      <mass value="10.0"/>
      <origin xyz="0 0 0"/>
      <inertia ixx="1.0" ixy="0.0" ixz="0.0" iyy="1.0" iyz="0.0" izz="1.0"/>
    </inertial>
  </link>

  <link name="upper_arm_link">
    <visual>
      <geometry><cylinder radius="0.05" length="0.3"/></geometry>
    </visual>
    <collision>
      <geometry><cylinder radius="0.05" length="0.3"/></geometry>
    </collision>
    <inertial>
      <mass value="1.0"/>
      <origin xyz="0 0 0.15"/>
      <inertia ixx="0.01" ixy="0.0" ixz="0.0" iyy="0.01" iyz="0.0" izz="0.01"/>
    </inertial>
  </link>

  <joint name="shoulder_joint" type="revolute">
    <parent link="base_link"/>
    <child link="upper_arm_link"/>
    <origin xyz="0 0.2 0.3" rpy="0 0 0"/>
    <axis xyz="0 1 0"/>
    <limit lower="-1.57" upper="1.57" effort="100" velocity="10"/>
  </joint>

  <!-- ... more links and joints would follow for a full humanoid ... -->

</robot>
